Workbook

Sheet ورقة1
A1: اسم المادة | B1: كود | C1: باركود | D1: عدد التعبئة | E1: سعر | F1: الشركات | G1: عدد الباقي | H1: القسم
A2: =[1]المقارنة!B2 -> ملبس حذاء 60 سم دنيا | B2: 00748 | C2: =[1]المقارنة!C2 -> 8696287080105 | D2: =[1]المقارنة!D2 -> 60 | E2: =[1]المقارنة!F2 -> 1250 | F2: =[1]المقارنة!K2 -> DUNYA | G2: =[1]المقارنة!I2 -> 0 | H2: =[1]المقارنة!L2 -> ملبس حذاء
A3: =[1]المقارنة!B3 -> سلة اوساخ 5 لتر كلاج دنيا | B3: 01010 | C3: =[1]المقارنة!C3 -> 8696287010102 | D3: =[1]المقارنة!D3 -> 12 | E3: =[1]المقارنة!F3 -> 8500 | F3: =[1]المقارنة!K3 -> DUNYA | G3: =[1]المقارنة!I3 -> 46 | H3: =[1]المقارنة!L3 -> سلة اوساخ
A4: =[1]المقارنة!B4 -> سلة اوساخ 7 لتر كلاج دنيا | B4: 01011 | C4: =[1]المقارنة!C4 -> 8696287010119 | D4: =[1]المقارنة!D4 -> 6 | E4: =[1]المقارنة!F4 -> 9500 | F4: =[1]المقارنة!K4 -> DUNYA | G4: =[1]المقارنة!I4 -> 10 | H4: =[1]المقارنة!L4 -> سلة اوساخ
A5: =[1]المقارنة!B5 -> سلة اوساخ 11 لتر كلاج دنيا | B5: 01012 | C5: =[1]المقارنة!C5 -> 8696287010126 | D5: =[1]المقارنة!D5 -> 6 | E5: =[1]المقارنة!F5 -> 14000 | F5: =[1]المقارنة!K5 -> DUNYA | G5: =[1]المقارنة!I5 -> 10 | H5: =[1]المقارنة!L5 -> سلة اوساخ
A6: =[1]المقارنة!B6 -> سلة اوساخ 18 لتر كلاج دنيا | B6: 01013 | C6: =[1]المقارنة!C6 -> 8696287010133 | D6: =[1]المقارنة!D6 -> 6 | E6: =[1]المقارنة!F6 -> 19000 | F6: =[1]المقارنة!K6 -> DUNYA | G6: =[1]المقارنة!I6 -> 6 | H6: =[1]المقارنة!L6 -> سلة اوساخ
A7: =[1]المقارنة!B7 -> سلة اوساخ 30 لتر كلاج دنيا | B7: 01014 | C7: =[1]المقارنة!C7 -> 8696287010140 | D7: =[1]المقارنة!D7 -> 4 | E7: =[1]المقارنة!F7 -> 26000 | F7: =[1]المقارنة!K7 -> DUNYA | G7: =[1]المقارنة!I7 -> 0 | H7: =[1]المقارنة!L7 -> سلة اوساخ
A8: =[1]المقارنة!B8 -> سلة اوساخ 50 لتر كلاج دنيا | B8: 01015 | C8: =[1]المقارنة!C8 -> 8696287010157 | D8: =[1]المقارنة!D8 -> 2 | E8: =[1]المقارنة!F8 -> 40000 | F8: =[1]المقارنة!K8 -> DUNYA | G8: =[1]المقارنة!I8 -> 32 | H8: =[1]المقارنة!L8 -> سلة اوساخ
A9: =[1]المقارنة!B9 -> سلة اوساخ 10 لتر سليم كلاج دنيا | B9: 01041 | C9: =[1]المقارنة!C9 -> 8696287010416 | D9: =[1]المقارنة!D9 -> 18 | E9: =[1]المقارنة!F9 -> 7500 | F9: =[1]المقارنة!K9 -> DUNYA | G9: =[1]المقارنة!I9 -> 0 | H9: =[1]المقارنة!L9 -> سلة اوساخ
A10: =[1]المقارنة!B10 -> سلة اوساخ 15 لتر سليم كلاج دنيا | B10: 01042 | C10: =[1]المقارنة!C10 -> 8696287010423 | D10: =[1]المقارنة!D10 -> 14 | E10: =[1]المقارنة!F10 -> 9500 | F10: =[1]المقارنة!K10 -> DUNYA | G10: =[1]المقارنة!I10 -> 0 | H10: =[1]المقارنة!L10 -> سلة اوساخ
A11: =[1]المقارنة!B11 -> سلة اوساخ 25 لتر سليم كلاج دنيا | B11: 01043 | C11: =[1]المقارنة!C11 -> 8696287010430 | D11: =[1]المقارنة!D11 -> 8 | E11: =[1]المقارنة!F11 -> 13500 | F11: =[1]المقارنة!K11 -> DUNYA | G11: =[1]المقارنة!I11 -> 0 | H11: =[1]المقارنة!L11 -> سلة اوساخ
A12: =[1]المقارنة!B12 -> سلة اوساخ 40 لتر سليم كلاج دنيا | B12: 01044 | C12: =[1]المقارنة!C12 -> 8696287010447 | D12: =[1]المقارنة!D12 -> 6 | E12: =[1]المقارنة!F12 -> 21000 | F12: =[1]المقارنة!K12 -> DUNYA | G12: =[1]المقارنة!I12 -> 0 | H12: =[1]المقارنة!L12 -> سلة اوساخ
A13: =[1]المقارنة!B13 -> سلة اوساخ 60 لتر سليم كلاج دنيا | B13: 01045 | C13: =[1]المقارنة!C13 -> 8696287010454 | D13: =[1]المقارنة!D13 -> 4 | E13: =[1]المقارنة!F13 -> 38000 | F13: =[1]المقارنة!K13 -> DUNYA | G13: =[1]المقارنة!I13 -> 5 | H13: =[1]المقارنة!L13 -> سلة اوساخ
... A57: =[1]المقارنة!B57 -> سلة اوساخ 50 لتر ايزي دنيا | B57: 09715 | C57: =[1]المقارنة!C57 -> 8696287097158 | D57: =[1]المقارنة!D57 -> 6 | E57: =[1]المقارنة!F57 -> 20000 | F57: =[1]المقارنة!K57 -> DUNYA | G57: =[1]المقارنة!I57 -> 12 | H57: =[1]المقارنة!L57 -> سلة اوساخ
A58: =[1]المقارنة!B58 -> دولكة عجين 1600 مل شفاف دنيا | B58: =[1]المقارنة!A58 -> 10201 | C58: =[1]المقارنة!C58 -> 8696287102012 | D58: =[1]المقارنة!D58 -> 24 | E58: =[1]المقارنة!F58 -> 2500 | F58: =[1]المقارنة!K58 -> DUNYA | G58: =[1]المقارنة!I58 -> 0 | H58: =[1]المقارنة!L58 -> دولكة عجين
A59: =[1]المقارنة!B59 -> كاسة عجين 3 لتر شفاف دنيا | B59: =[1]المقارنة!A59 -> 10208 | C59: =[1]المقارنة!C59 -> 8696287102081 | D59: =[1]المقارنة!D59 -> 60 | E59: =[1]المقارنة!F59 -> 2250 | F59: =[1]المقارنة!K59 -> DUNYA | G59: =[1]المقارنة!I59 -> 108 | H59: =[1]المقارنة!L59 -> كاسة عجين
A60: =[1]المقارنة!B60 -> كاسة عجين 5 لتر شفاف دنيا | B60: =[1]المقارنة!A60 -> 10209 | C60: =[1]المقارنة!C60 -> 8696287102098 | D60: =[1]المقارنة!D60 -> 50 | E60: =[1]المقارنة!F60 -> 2750 | F60: =[1]المقارنة!K60 -> DUNYA | G60: =[1]المقارنة!I60 -> 90 | H60: =[1]المقارنة!L60 -> كاسة عجين
A61: =[1]المقارنة!B61 -> سلة خضراوات 700 مل دنيا | B61: =[1]المقارنة!A61 -> 10215 | C61: =[1]المقارنة!C61 -> 8696287102159 | D61: =[1]المقارنة!D61 -> 160 | E61: =[1]المقارنة!F61 -> 750 | F61: =[1]المقارنة!K61 -> DUNYA | G61: =[1]المقارنة!I61 -> 113 | H61: =[1]المقارنة!L61 -> سلة خضراوات
A62: =[1]المقارنة!B62 -> سلة خضراوات 1200 مل دنيا | B62: =[1]المقارنة!A62 -> 10232 | C62: =[1]المقارنة!C62 -> 8696287102326 | D62: =[1]المقارنة!D62 -> 160 | E62: =[1]المقارنة!F62 -> 937.5 | F62: =[1]المقارنة!K62 -> DUNYA | G62: =[1]المقارنة!I62 -> 0 | H62: =[1]المقارنة!L62 -> سلة خضراوات
A63: =[1]المقارنة!B63 -> انجانة 2.7 لتر بلاستك دنيا | B63: =[1]المقارنة!A63 -> 10323 | C63: =[1]المقارنة!C63 -> 8696287103231 | D63: =[1]المقارنة!D63 -> 100 | E63: =[1]المقارنة!F63 -> 1250 | F63: =[1]المقارنة!K63 -> DUNYA | G63: =[1]المقارنة!I63 -> 82 | H63: =[1]المقارنة!L63 -> انجانة 2.7 لتر
A64: =[1]المقارنة!B64 -> انجانة 4.5 لتر بلاستك دنيا | B64: =[1]المقارنة!A64 -> 10324 | C64: =[1]المقارنة!C64 -> 8696287103248 | D64: =[1]المقارنة!D64 -> 100 | E64: =[1]المقارنة!F64 -> 1750 | F64: =[1]المقارنة!K64 -> DUNYA | G64: =[1]المقارنة!I64 -> 94 | H64: =[1]المقارنة!L64 -> انجانة 4.5 لتر
A65: =[1]المقارنة!B65 -> انجانة 7 لتر بلاستك دنيا | B65: =[1]المقارنة!A65 -> 10325 | C65: =[1]المقارنة!C65 -> 8696287103255 | D65: =[1]المقارنة!D65 -> 48 | E65: =[1]المقارنة!F65 -> 2250 | F65: =[1]المقارنة!K65 -> DUNYA | G65: =[1]المقارنة!I65 -> 42 | H65: =[1]المقارنة!L65 -> انجانة 7 لتر
A66: =[1]المقارنة!B66 -> انجانة 10.5 لتر بلاستك دنيا | B66: =[1]المقارنة!A66 -> 10326 | C66: =[1]المقارنة!C66 -> 8696287103262 | D66: =[1]المقارنة!D66 -> 48 | E66: =[1]المقارنة!F66 -> 3000 | F66: =[1]المقارنة!K66 -> DUNYA | G66: =[1]المقارنة!I66 -> 42 | H66: =[1]المقارنة!L66 -> انجانة 10.5 لتر
A67: =[1]المقارنة!B67 -> انجانة 1.7 لتر شفاف دنيا | B67: =[1]المقارنة!A67 -> 10332 | C67: =[1]المقارنة!C67 -> 8696287103323 | D67: =[1]المقارنة!D67 -> 100 | E67: =[1]المقارنة!F67 -> 1000 | F67: =[1]المقارنة!K67 -> DUNYA | G67: =[1]المقارنة!I67 -> 74 | H67: =[1]المقارنة!L67 -> انجانة 1.7 لتر
A68: =[1]المقارنة!B68 -> انجانة 2.7 لتر شفاف دنيا | B68: =[1]المقارنة!A68 -> 10333 | C68: =[1]المقارنة!C68 -> 8696287103330 | D68: =[1]المقارنة!D68 -> 100 | E68: =[1]المقارنة!F68 -> 1500 | F68: =[1]المقارنة!K68 -> DUNYA | G68: =[1]المقارنة!I68 -> 46 | H68: =[1]المقارنة!L68 -> انجانة 2.7 لتر
A69: =[1]المقارنة!B69 -> انجانة 4.5 لتر شفاف دنيا | B69: =[1]المقارنة!A69 -> 10334 | C69: =[1]المقارنة!C69 -> 8696287103347 | D69: =[1]المقارنة!D69 -> 100 | E69: =[1]المقارنة!F69 -> 1750 | F69: =[1]المقارنة!K69 -> DUNYA | G69: =[1]المقارنة!I69 -> 62 | H69: =[1]المقارنة!L69 -> انجانة 4.5 لتر
... A329: =[1]المقارنة!B329 -> سلة اوساخ كلاج 32 لتر بورسيف | B329: =[1]المقارنة!A329 -> 415004 | C329: =[1]المقارنة!C329 -> 8694917002251 | D329: =[1]المقارنة!D329 -> 2 | E329: =[1]المقارنة!F329 -> 25000 | F329: =[1]المقارنة!K329 -> BURSEV | G329: =[1]المقارنة!I329 -> 0 | H329: =[1]المقارنة!L329 -> سلة اوساخ
A330: =[1]المقارنة!B331 -> سيت سلة اوساخ كلاج ثلاثي بورسيف | B330: =[1]المقارنة!A331 -> 415011 | C330: =[1]المقارنة!C331 -> 8694917008154 | D330: =[1]المقارنة!D331 -> 1 | E330: =[1]المقارنة!F331 -> 36000 | F330: =[1]المقارنة!K331 -> BURSEV | G330: =[1]المقارنة!I331 -> 12 | H330: =[1]المقارنة!L331 -> سيت سلة
A331: =[1]المقارنة!B332 -> سلة اوساخ 4 لتر رقم 1 بورسيف | B331: =[1]المقارنة!A332 -> 415101 | C331: =[1]المقارنة!C332 -> 8694917002435 | D331: =[1]المقارنة!D332 -> 24 | E331: =[1]المقارنة!F332 -> 3500 | F331: =[1]المقارنة!K332 -> BURSEV | G331: =[1]المقارنة!I332 -> 96 | H331: =[1]المقارنة!L332 -> سلة اوساخ
A332: =[1]المقارنة!B333 -> سلة اوساخ 7 لتر رقم 2 بورسيف | B332: =[1]المقارنة!A333 -> 415102 | C332: =[1]المقارنة!C333 -> 8694917002381 | D332: =[1]المقارنة!D333 -> 24 | E332: =[1]المقارنة!F333 -> 6000 | F332: =[1]المقارنة!K333 -> BURSEV | G332: =[1]المقارنة!I333 -> 102 | H332: =[1]المقارنة!L333 -> سلة اوساخ
A333: =[1]المقارنة!B334 -> سلة اوساخ 13 لتر رقم 3 بورسيف | B333: =[1]المقارنة!A334 -> 415103 | C333: =[1]المقارنة!C334 -> 8694917002268 | D333: =[1]المقارنة!D334 -> 16 | E333: =[1]المقارنة!F334 -> 8500 | F333: =[1]المقارنة!K334 -> BURSEV | G333: =[1]المقارنة!I334 -> 58 | H333: =[1]المقارنة!L334 -> سلة اوساخ
A334: =[1]المقارنة!B335 -> سلة اوساخ 22 لتر رقم 4 بورسيف | B334: =[1]المقارنة!A335 -> 415104 | C334: =[1]المقارنة!C335 -> 8694917002183 | D334: =[1]المقارنة!D335 -> 12 | E334: =[1]المقارنة!F335 -> 13000 | F334: =[1]المقارنة!K335 -> BURSEV | G334: =[1]المقارنة!I335 -> 81 | H334: =[1]المقارنة!L335 -> سلة اوساخ
A335: =[1]المقارنة!B336 -> سلة اوساخ رقم 2 بليكانو 5 لتر بورسيف | B335: =[1]المقارنة!A336 -> 415202 | C335: =[1]المقارنة!C336 -> 8694917007140 | D335: =[1]المقارنة!D336 -> 36 | E335: =[1]المقارنة!F336 -> 2400 | F335: =[1]المقارنة!K336 -> BURSEV | G335: =[1]المقارنة!I336 -> 0 | H335: =[1]المقارنة!L336 -> سلة اوساخ
A336: =[1]المقارنة!B337 -> سلة اوساخ رقم 3 بليكانو 10لتر بورسيف | B336: =[1]المقارنة!A337 -> 415203 | C336: =[1]المقارنة!C337 -> 8694917007157 | D336: =[1]المقارنة!D337 -> 24 | E336: =[1]المقارنة!F337 -> 4125 | F336: =[1]المقارنة!K337 -> BURSEV | G336: =[1]المقارنة!I337 -> 0 | H336: =[1]المقارنة!L337 -> سلة اوساخ
A337: =[1]المقارنة!B338 -> سلة اوساخ رقم 4 بليكانو 22 لتر بورسيف | B337: =[1]المقارنة!A338 -> 415204 | C337: =[1]المقارنة!C338 -> 8694917007164 | D337: =[1]المقارنة!D338 -> 12 | E337: =[1]المقارنة!F338 -> 6750 | F337: =[1]المقارنة!K338 -> BURSEV | G337: =[1]المقارنة!I338 -> 0 | H337: =[1]المقارنة!L338 -> سلة اوساخ
A338: =[1]المقارنة!B339 -> سلة اوساخ رقم 5 بليكانو 35 لتر بورسيف | B338: =[1]المقارنة!A339 -> 415205 | C338: =[1]المقارنة!C339 -> 8694917007171 | D338: =[1]المقارنة!D339 -> 5 | E338: =[1]المقارنة!F339 -> 11000 | F338: =[1]المقارنة!K339 -> BURSEV | G338: =[1]المقارنة!I339 -> 0 | H338: =[1]المقارنة!L339 -> سلة اوساخ
A339: =[1]المقارنة!B340 -> سلة اوساخ رقم 6 بليكانو 52 لتر بورسيف | B339: =[1]المقارنة!A340 -> 415286 | C339: =[1]المقارنة!C340 -> 8694917007416 | D339: =[1]المقارنة!D340 -> 6 | E339: =[1]المقارنة!F340 -> 14000 | F339: =[1]المقارنة!K340 -> BURSEV | G339: =[1]المقارنة!I340 -> 0 | H339: =[1]المقارنة!L340 -> سلة اوساخ
A340: =[1]المقارنة!B341 -> سطل 12 لتر ربل قابل للطي | B340: =[1]المقارنة!A341 -> 50017 | C340: =[1]المقارنة!C341 -> 8696287500177 | D340: =[1]المقارنة!D341 -> 10 | E340: =[1]المقارنة!F341 -> 7000 | F340: =[1]المقارنة!K341 -> DUNYA | G340: =[1]المقارنة!I341 -> 18 | H340: =[1]المقارنة!L341 -> سطل 12 لتر
A341: =[1]المقارنة!B342 -> سلة طوابق مستطيل سليم بورسيف | B341: =[1]المقارنة!A342 -> 515801 | C341: =[1]المقارنة!C342 -> 8694917006419 | D341: =[1]المقارنة!D342 -> 8 | E341: =[1]المقارنة!F342 -> 12000 | F341: =[1]المقارنة!K342 -> BURSEV | G341: =[1]المقارنة!I342 -> 0 | H341: =[1]المقارنة!L342 -> سلة طوابق
... A456: =[1]المقارنة!B457 -> ضاغطة همبركر بارونيس | B456: =[1]المقارنة!A457 -> BA001 | C456: =[1]المقارنة!C457 -> 8682013310011 | D456: =[1]المقارنة!D457 -> 120 | E456: =[1]المقارنة!F457 -> 2000 | F456: =[1]المقارنة!K457 -> BARONESS | G456: =[1]المقارنة!I457 -> 0 | H456: =[1]المقارنة!L457 -> ضاغطة همبركر
...
